import React from 'react';
import { render, screen, fireEvent } from '@testing-library/react';
import ErrorBoundary from '../ErrorBoundary';

const ThrowError = () => {
  throw new Error('Test error');
};

describe('ErrorBoundary', () => {
  beforeEach(() => {
    jest.spyOn(console, 'error').mockImplementation(() => {});
  });

  afterEach(() => {
    jest.restoreAllMocks();
  });

  it('renders children when there is no error', () => {
    render(
      <ErrorBoundary>
        <div>Test content</div>
      </ErrorBoundary>
    );

    expect(screen.getByText('Test content')).toBeInTheDocument();
  });

  it('renders error UI when there is an error', () => {
    render(
      <ErrorBoundary>
        <ThrowError />
      </ErrorBoundary>
    );

    expect(screen.getByText('Something went wrong')).toBeInTheDocument();
    expect(screen.getByText('Test error')).toBeInTheDocument();
    expect(screen.getByRole('button', { name: /try again/i })).toBeInTheDocument();
  });

  it('renders custom fallback when provided', () => {
    const fallback = <div>Custom error UI</div>;

    render(
      <ErrorBoundary fallback={fallback}>
        <ThrowError />
      </ErrorBoundary>
    );

    expect(screen.getByText('Custom error UI')).toBeInTheDocument();
  });

  it('resets error state when Try Again is clicked', () => {
    render(
      <ErrorBoundary>
        <ThrowError />
      </ErrorBoundary>
    );

    expect(screen.getByText('Something went wrong')).toBeInTheDocument();

    fireEvent.click(screen.getByRole('button', { name: /try again/i }));

    // The error boundary should now render its children again
    expect(screen.queryByText('Something went wrong')).not.toBeInTheDocument();
  });
}); 